<?xml version="1.0" ?>
<!--
  Simple Robot Model for Module 2 Examples

  This is a basic two-link robot arm for demonstrating
  Gazebo fundamentals, sensors, and control integration.
-->
<sdf version="1.9">
  <model name="simple_robot">
    <static>false</static>

    <!-- Base Link (fixed to world) -->
    <link name="base_link">
      <pose>0 0 0.1 0 0 0</pose>
      <inertial>
        <mass>5.0</mass>
        <inertia>
          <ixx>0.1</ixx>
          <iyy>0.1</iyy>
          <izz>0.1</izz>
        </inertia>
      </inertial>
      <visual name="base_visual">
        <geometry>
          <cylinder>
            <radius>0.1</radius>
            <length>0.2</length>
          </cylinder>
        </geometry>
        <material>
          <ambient>0.2 0.2 0.8 1</ambient>
          <diffuse>0.2 0.2 0.8 1</diffuse>
        </material>
      </visual>
      <collision name="base_collision">
        <geometry>
          <cylinder>
            <radius>0.1</radius>
            <length>0.2</length>
          </cylinder>
        </geometry>
      </collision>
    </link>

    <!-- Upper Arm Link -->
    <link name="upper_arm">
      <pose>0 0 0.35 0 0 0</pose>
      <inertial>
        <mass>2.0</mass>
        <inertia>
          <ixx>0.02</ixx>
          <iyy>0.02</iyy>
          <izz>0.01</izz>
        </inertia>
      </inertial>
      <visual name="upper_arm_visual">
        <geometry>
          <box>
            <size>0.05 0.05 0.3</size>
          </box>
        </geometry>
        <material>
          <ambient>0.8 0.2 0.2 1</ambient>
          <diffuse>0.8 0.2 0.2 1</diffuse>
        </material>
      </visual>
      <collision name="upper_arm_collision">
        <geometry>
          <box>
            <size>0.05 0.05 0.3</size>
          </box>
        </geometry>
      </collision>
    </link>

    <!-- Lower Arm Link -->
    <link name="lower_arm">
      <pose>0 0 0.6 0 0 0</pose>
      <inertial>
        <mass>1.0</mass>
        <inertia>
          <ixx>0.01</ixx>
          <iyy>0.01</iyy>
          <izz>0.005</izz>
        </inertia>
      </inertial>
      <visual name="lower_arm_visual">
        <geometry>
          <box>
            <size>0.04 0.04 0.2</size>
          </box>
        </geometry>
        <material>
          <ambient>0.2 0.8 0.2 1</ambient>
          <diffuse>0.2 0.8 0.2 1</diffuse>
        </material>
      </visual>
      <collision name="lower_arm_collision">
        <geometry>
          <box>
            <size>0.04 0.04 0.2</size>
          </box>
        </geometry>
      </collision>
    </link>

    <!-- Shoulder Joint -->
    <joint name="shoulder_joint" type="revolute">
      <parent>base_link</parent>
      <child>upper_arm</child>
      <pose>0 0 -0.15 0 0 0</pose>
      <axis>
        <xyz>0 1 0</xyz>
        <limit>
          <lower>-1.57</lower>
          <upper>1.57</upper>
          <effort>100</effort>
          <velocity>1.0</velocity>
        </limit>
        <dynamics>
          <damping>0.5</damping>
          <friction>0.1</friction>
        </dynamics>
      </axis>
    </joint>

    <!-- Elbow Joint -->
    <joint name="elbow_joint" type="revolute">
      <parent>upper_arm</parent>
      <child>lower_arm</child>
      <pose>0 0 -0.1 0 0 0</pose>
      <axis>
        <xyz>0 1 0</xyz>
        <limit>
          <lower>-2.0</lower>
          <upper>2.0</upper>
          <effort>50</effort>
          <velocity>1.0</velocity>
        </limit>
        <dynamics>
          <damping>0.3</damping>
          <friction>0.1</friction>
        </dynamics>
      </axis>
    </joint>

    <!-- Fixed joint to world (comment out for free-standing robot) -->
    <joint name="world_joint" type="fixed">
      <parent>world</parent>
      <child>base_link</child>
    </joint>

  </model>
</sdf>
